<?xml version="1.0" ?>
<!-- =================================================================================== -->
<!-- |    This document was autogenerated by xacro from /home/matej/r-modus/sw-nav-module/rmodus_sim/urdf/robot.urdf.xacro | -->
<!-- |    EDITING THIS FILE BY HAND IS NOT RECOMMENDED                                 | -->
<!-- =================================================================================== -->
<!-- Simulation robot description.
     Includes the shared base from rmodus_description and adds Gazebo plugins. -->
<robot name="my_robot" xmlns:gz="http://gazebosim.org/schema">
  <material name="base_mat">
    <color rgba="0.24 0.26 0.29 1.0"/>
  </material>
  <material name="main_module_mat">
    <color rgba="0.42 0.45 0.49 1.0"/>
  </material>
  <material name="wheel_mat">
    <color rgba="0.1 0.1 0.11 1.0"/>
  </material>
  <material name="imu_mount_mat">
    <color rgba="0.76 0.66 0.88 1.0"/>
  </material>
  <material name="imu_link_mat">
    <color rgba="0.88 0.82 0.95 1.0"/>
  </material>
  <material name="lidar_mount_mat">
    <color rgba="0.2 0.48 0.72 1.0"/>
  </material>
  <material name="lidar_beam_mat">
    <color rgba="0.34 0.7 0.93 1.0"/>
  </material>
  <material name="bumper_mount_mat">
    <color rgba="0.68 0.2 0.2 1.0"/>
  </material>
  <material name="bumper_contact_mat">
    <color rgba="0.9 0.24 0.24 1.0"/>
  </material>
  <material name="cliff_mount_mat">
    <color rgba="0.18 0.62 0.44 1.0"/>
  </material>
  <material name="cliff_beam_mat">
    <color rgba="0.4 0.79 0.56 1.0"/>
  </material>
  <link name="base_footprint"/>
  <link name="base_link">
    <inertial>
      <mass value="5.0"/>
      <inertia ixx="0.05208333333333333" ixy="0.0" ixz="0.0" iyy="0.05208333333333333" iyz="0.0" izz="0.10208333333333332"/>
    </inertial>
    <visual>
      <geometry>
        <box size="0.35 0.35 0.05"/>
      </geometry>
      <material name="base_mat"/>
    </visual>
    <collision>
      <geometry>
        <box size="0.35 0.35 0.05"/>
      </geometry>
    </collision>
  </link>
  <link name="main_module_mount">
    <visual>
      <origin rpy="0 0 0" xyz="0 0 0"/>
      <geometry>
        <box size="0.24 0.18 0.06"/>
      </geometry>
      <material name="main_module_mat"/>
    </visual>
  </link>
  <joint name="body_link_joint" type="fixed">
    <parent link="base_footprint"/>
    <child link="base_link"/>
    <origin rpy="0 0 0" xyz="0 0 0.1"/>
  </joint>
  <joint name="main_module_mount_joint" type="fixed">
    <parent link="base_link"/>
    <child link="main_module_mount"/>
    <origin rpy="0.0 0.0 0.0" xyz="0.08 0.0 0.035"/>
  </joint>
  <link name="imu_mount">
    <inertial>
      <origin rpy="0 0 0" xyz="0 0 0.005"/>
      <mass value="0.01"/>
      <inertia ixx="1e-6" ixy="0" ixz="0" iyy="1e-6" iyz="0" izz="1e-6"/>
    </inertial>
    <collision>
      <origin rpy="0 0 0" xyz="0 0 0.005"/>
      <geometry>
        <box size="0.02 0.02 0.01"/>
      </geometry>
    </collision>
    <visual>
      <origin rpy="0 0 0" xyz="0 0 0.005"/>
      <geometry>
        <box size="0.02 0.02 0.01"/>
      </geometry>
      <material name="imu_mount_mat"/>
    </visual>
  </link>
  <link name="imu_link">
    <inertial>
      <mass value="0.001"/>
      <inertia ixx="1e-7" ixy="0" ixz="0" iyy="1e-7" iyz="0" izz="1e-7"/>
    </inertial>
  </link>
  <joint name="imu_mount_joint" type="fixed">
    <parent link="main_module_mount"/>
    <child link="imu_mount"/>
    <origin rpy="0.0 0.0 0.0" xyz="-0.01 0.05 0.03"/>
  </joint>
  <joint name="imu_joint" type="fixed">
    <parent link="imu_mount"/>
    <child link="imu_link"/>
    <origin rpy="0.0 0.0 0.0" xyz="0.0 0.0 0.03"/>
  </joint>
  <link name="lidar_mount">
    <inertial>
      <origin rpy="0 0 0" xyz="0 0 0.01"/>
      <mass value="0.02"/>
      <inertia ixx="2e-6" ixy="0" ixz="0" iyy="2e-6" iyz="0" izz="2e-6"/>
    </inertial>
    <collision>
      <origin rpy="0 0 0" xyz="0 0 0.01"/>
      <geometry>
        <cylinder length="0.02" radius="0.01"/>
      </geometry>
    </collision>
    <visual>
      <origin rpy="0 0 0" xyz="0 0 0.01"/>
      <geometry>
        <cylinder length="0.02" radius="0.01"/>
      </geometry>
      <material name="lidar_mount_mat"/>
    </visual>
  </link>
  <link name="lidar_beam">
    <inertial>
      <mass value="0.001"/>
      <inertia ixx="1e-7" ixy="0" ixz="0" iyy="1e-7" iyz="0" izz="1e-7"/>
    </inertial>
  </link>
  <joint name="lidar_mount_joint" type="fixed">
    <parent link="main_module_mount"/>
    <child link="lidar_mount"/>
    <origin rpy="0.0 0.0 0.0" xyz="0.07 0.0 0.03"/>
  </joint>
  <joint name="lidar_joint" type="fixed">
    <parent link="lidar_mount"/>
    <child link="lidar_beam"/>
    <origin rpy="0.0 0.0 0.0" xyz="0.0 0.0 0.02"/>
  </joint>
  <link name="bumper_front_mount">
    <inertial>
      <mass value="0.001"/>
      <inertia ixx="0.00001" ixy="0" ixz="0" iyy="0.00001" iyz="0" izz="0.00001"/>
    </inertial>
    <visual>
      <origin rpy="0 0 0" xyz="0.015 0 -0.03"/>
      <geometry>
        <box size="0.03 0.34 0.06"/>
      </geometry>
      <material name="bumper_mount_mat"/>
    </visual>
    <collision>
      <origin rpy="0 0 0" xyz="0.015 0 -0.03"/>
      <geometry>
        <box size="0.03 0.34 0.06"/>
      </geometry>
    </collision>
  </link>
  <link name="bumper_front_contact"/>
  <joint name="bumper_front_mount_joint" type="fixed">
    <parent link="base_link"/>
    <child link="bumper_front_mount"/>
    <origin rpy="0.0 0.0 0.0" xyz="0.33 0.0 0.0"/>
  </joint>
  <joint name="bumper_front_contact_joint" type="fixed">
    <parent link="bumper_front_mount"/>
    <child link="bumper_front_contact"/>
    <origin rpy="0.0 0.0 0.0" xyz="0.031 0.0 -0.03"/>
  </joint>
  <link name="bumper_rear_mount">
    <inertial>
      <mass value="0.001"/>
      <inertia ixx="0.00001" ixy="0" ixz="0" iyy="0.00001" iyz="0" izz="0.00001"/>
    </inertial>
    <visual>
      <origin rpy="0 0 0" xyz="0.015 0 -0.03"/>
      <geometry>
        <box size="0.03 0.34 0.06"/>
      </geometry>
      <material name="bumper_mount_mat"/>
    </visual>
    <collision>
      <origin rpy="0 0 0" xyz="0.015 0 -0.03"/>
      <geometry>
        <box size="0.03 0.34 0.06"/>
      </geometry>
    </collision>
  </link>
  <link name="bumper_rear_contact"/>
  <joint name="bumper_rear_mount_joint" type="fixed">
    <parent link="base_link"/>
    <child link="bumper_rear_mount"/>
    <origin rpy="0.0 0.0 3.14159" xyz="-0.33 0.0 0.0"/>
  </joint>
  <joint name="bumper_rear_contact_joint" type="fixed">
    <parent link="bumper_rear_mount"/>
    <child link="bumper_rear_contact"/>
    <origin rpy="0.0 0.0 0.0" xyz="0.031 0.0 -0.03"/>
  </joint>
  <link name="bumper_left_mount">
    <inertial>
      <mass value="0.001"/>
      <inertia ixx="0.00001" ixy="0" ixz="0" iyy="0.00001" iyz="0" izz="0.00001"/>
    </inertial>
    <visual>
      <origin rpy="0 0 0" xyz="0.015 0 -0.03"/>
      <geometry>
        <box size="0.03 0.24 0.06"/>
      </geometry>
      <material name="bumper_mount_mat"/>
    </visual>
    <collision>
      <origin rpy="0 0 0" xyz="0.015 0 -0.03"/>
      <geometry>
        <box size="0.03 0.24 0.06"/>
      </geometry>
    </collision>
  </link>
  <link name="bumper_left_contact"/>
  <joint name="bumper_left_mount_joint" type="fixed">
    <parent link="base_link"/>
    <child link="bumper_left_mount"/>
    <origin rpy="0.0 0.0 1.5708" xyz="0.0 0.25 0.0"/>
  </joint>
  <joint name="bumper_left_contact_joint" type="fixed">
    <parent link="bumper_left_mount"/>
    <child link="bumper_left_contact"/>
    <origin rpy="0.0 0.0 0.0" xyz="0.031 0.0 -0.03"/>
  </joint>
  <link name="bumper_right_mount">
    <inertial>
      <mass value="0.001"/>
      <inertia ixx="0.00001" ixy="0" ixz="0" iyy="0.00001" iyz="0" izz="0.00001"/>
    </inertial>
    <visual>
      <origin rpy="0 0 0" xyz="0.015 0 -0.03"/>
      <geometry>
        <box size="0.03 0.24 0.06"/>
      </geometry>
      <material name="bumper_mount_mat"/>
    </visual>
    <collision>
      <origin rpy="0 0 0" xyz="0.015 0 -0.03"/>
      <geometry>
        <box size="0.03 0.24 0.06"/>
      </geometry>
    </collision>
  </link>
  <link name="bumper_right_contact"/>
  <joint name="bumper_right_mount_joint" type="fixed">
    <parent link="base_link"/>
    <child link="bumper_right_mount"/>
    <origin rpy="0.0 0.0 -1.5708" xyz="0.0 -0.25 0.0"/>
  </joint>
  <joint name="bumper_right_contact_joint" type="fixed">
    <parent link="bumper_right_mount"/>
    <child link="bumper_right_contact"/>
    <origin rpy="0.0 0.0 0.0" xyz="0.031 0.0 -0.03"/>
  </joint>
  <link name="cliff_sensor_fl_mount">
    <inertial>
      <mass value="0.001"/>
      <inertia ixx="6.666666666666667e-08" ixy="0.0" ixz="0.0" iyy="6.666666666666667e-08" iyz="0.0" izz="6.666666666666667e-08"/>
    </inertial>
    <visual>
      <origin rpy="0 0 0" xyz="0.01 0 -0.01"/>
      <geometry>
        <box size="0.02 0.02 0.02"/>
      </geometry>
      <material name="cliff_mount_mat"/>
    </visual>
    <collision>
      <origin rpy="0 0 0" xyz="0.01 0 -0.01"/>
      <geometry>
        <box size="0.02 0.02 0.02"/>
      </geometry>
    </collision>
  </link>
  <joint name="cliff_sensor_fl_mount_joint" type="fixed">
    <parent link="base_link"/>
    <child link="cliff_sensor_fl_mount"/>
    <origin rpy="0.0 0.0 0.0" xyz="0.24 0.17 -0.045"/>
  </joint>
  <link name="cliff_sensor_fl_beam">
    <inertial>
      <mass value="0.001"/>
      <inertia ixx="0.00001" ixy="0" ixz="0" iyy="0.00001" iyz="0" izz="0.00001"/>
    </inertial>
  </link>
  <joint name="cliff_sensor_fl_beam_joint" type="fixed">
    <parent link="cliff_sensor_fl_mount"/>
    <child link="cliff_sensor_fl_beam"/>
    <origin rpy="0.1 1.5708 0.0" xyz="0.0 0.0 -0.02"/>
  </joint>
  <link name="cliff_sensor_fr_mount">
    <inertial>
      <mass value="0.001"/>
      <inertia ixx="6.666666666666667e-08" ixy="0.0" ixz="0.0" iyy="6.666666666666667e-08" iyz="0.0" izz="6.666666666666667e-08"/>
    </inertial>
    <visual>
      <origin rpy="0 0 0" xyz="0.01 0 -0.01"/>
      <geometry>
        <box size="0.02 0.02 0.02"/>
      </geometry>
      <material name="cliff_mount_mat"/>
    </visual>
    <collision>
      <origin rpy="0 0 0" xyz="0.01 0 -0.01"/>
      <geometry>
        <box size="0.02 0.02 0.02"/>
      </geometry>
    </collision>
  </link>
  <joint name="cliff_sensor_fr_mount_joint" type="fixed">
    <parent link="base_link"/>
    <child link="cliff_sensor_fr_mount"/>
    <origin rpy="0.0 0.0 0.0" xyz="0.24 -0.17 -0.045"/>
  </joint>
  <link name="cliff_sensor_fr_beam">
    <inertial>
      <mass value="0.001"/>
      <inertia ixx="0.00001" ixy="0" ixz="0" iyy="0.00001" iyz="0" izz="0.00001"/>
    </inertial>
  </link>
  <joint name="cliff_sensor_fr_beam_joint" type="fixed">
    <parent link="cliff_sensor_fr_mount"/>
    <child link="cliff_sensor_fr_beam"/>
    <origin rpy="0.1 1.5708 0.0" xyz="0.0 0.0 -0.02"/>
  </joint>
  <link name="cliff_sensor_rl_mount">
    <inertial>
      <mass value="0.001"/>
      <inertia ixx="6.666666666666667e-08" ixy="0.0" ixz="0.0" iyy="6.666666666666667e-08" iyz="0.0" izz="6.666666666666667e-08"/>
    </inertial>
    <visual>
      <origin rpy="0 0 0" xyz="0.01 0 -0.01"/>
      <geometry>
        <box size="0.02 0.02 0.02"/>
      </geometry>
      <material name="cliff_mount_mat"/>
    </visual>
    <collision>
      <origin rpy="0 0 0" xyz="0.01 0 -0.01"/>
      <geometry>
        <box size="0.02 0.02 0.02"/>
      </geometry>
    </collision>
  </link>
  <joint name="cliff_sensor_rl_mount_joint" type="fixed">
    <parent link="base_link"/>
    <child link="cliff_sensor_rl_mount"/>
    <origin rpy="0.0 0.0 3.14159" xyz="-0.24 0.17 -0.045"/>
  </joint>
  <link name="cliff_sensor_rl_beam">
    <inertial>
      <mass value="0.001"/>
      <inertia ixx="0.00001" ixy="0" ixz="0" iyy="0.00001" iyz="0" izz="0.00001"/>
    </inertial>
  </link>
  <joint name="cliff_sensor_rl_beam_joint" type="fixed">
    <parent link="cliff_sensor_rl_mount"/>
    <child link="cliff_sensor_rl_beam"/>
    <origin rpy="0.1 1.5708 0.0" xyz="0.0 0.0 -0.02"/>
  </joint>
  <link name="cliff_sensor_rr_mount">
    <inertial>
      <mass value="0.001"/>
      <inertia ixx="6.666666666666667e-08" ixy="0.0" ixz="0.0" iyy="6.666666666666667e-08" iyz="0.0" izz="6.666666666666667e-08"/>
    </inertial>
    <visual>
      <origin rpy="0 0 0" xyz="0.01 0 -0.01"/>
      <geometry>
        <box size="0.02 0.02 0.02"/>
      </geometry>
      <material name="cliff_mount_mat"/>
    </visual>
    <collision>
      <origin rpy="0 0 0" xyz="0.01 0 -0.01"/>
      <geometry>
        <box size="0.02 0.02 0.02"/>
      </geometry>
    </collision>
  </link>
  <joint name="cliff_sensor_rr_mount_joint" type="fixed">
    <parent link="base_link"/>
    <child link="cliff_sensor_rr_mount"/>
    <origin rpy="0.0 0.0 3.14159" xyz="-0.24 -0.17 -0.045"/>
  </joint>
  <link name="cliff_sensor_rr_beam">
    <inertial>
      <mass value="0.001"/>
      <inertia ixx="0.00001" ixy="0" ixz="0" iyy="0.00001" iyz="0" izz="0.00001"/>
    </inertial>
  </link>
  <joint name="cliff_sensor_rr_beam_joint" type="fixed">
    <parent link="cliff_sensor_rr_mount"/>
    <child link="cliff_sensor_rr_beam"/>
    <origin rpy="0.0 1.5708 0.0" xyz="0.1 0.0 -0.02"/>
  </joint>
  <!-- WHEELS -->
  <link name="front_left_wheel">
    <inertial>
      <mass value="0.5"/>
      <inertia ixx="0.0006050000000000001" ixy="0.0" ixz="0.0" iyy="0.0006050000000000001" iyz="0.0" izz="0.0006050000000000001"/>
    </inertial>
    <visual>
      <geometry>
        <sphere radius="0.055"/>
      </geometry>
      <material name="wheel_mat"/>
    </visual>
    <collision>
      <geometry>
        <sphere radius="0.055"/>
      </geometry>
    </collision>
  </link>
  <link name="front_right_wheel">
    <inertial>
      <mass value="0.5"/>
      <inertia ixx="0.0006050000000000001" ixy="0.0" ixz="0.0" iyy="0.0006050000000000001" iyz="0.0" izz="0.0006050000000000001"/>
    </inertial>
    <visual>
      <geometry>
        <sphere radius="0.055"/>
      </geometry>
      <material name="wheel_mat"/>
    </visual>
    <collision>
      <geometry>
        <sphere radius="0.055"/>
      </geometry>
    </collision>
  </link>
  <link name="rear_left_wheel">
    <inertial>
      <mass value="0.5"/>
      <inertia ixx="0.0006050000000000001" ixy="0.0" ixz="0.0" iyy="0.0006050000000000001" iyz="0.0" izz="0.0006050000000000001"/>
    </inertial>
    <visual>
      <geometry>
        <sphere radius="0.055"/>
      </geometry>
      <material name="wheel_mat"/>
    </visual>
    <collision>
      <geometry>
        <sphere radius="0.055"/>
      </geometry>
    </collision>
  </link>
  <link name="rear_right_wheel">
    <inertial>
      <mass value="0.5"/>
      <inertia ixx="0.0006050000000000001" ixy="0.0" ixz="0.0" iyy="0.0006050000000000001" iyz="0.0" izz="0.0006050000000000001"/>
    </inertial>
    <visual>
      <geometry>
        <sphere radius="0.055"/>
      </geometry>
      <material name="wheel_mat"/>
    </visual>
    <collision>
      <geometry>
        <sphere radius="0.055"/>
      </geometry>
    </collision>
  </link>
  <joint name="front_left_wheel_joint" type="continuous">
    <parent link="base_link"/>
    <child link="front_left_wheel"/>
    <origin rpy="-1.5707963267948966 0 0" xyz="0.12 0.19 -0.06"/>
    <axis xyz="0 0 1"/>
  </joint>
  <joint name="front_right_wheel_joint" type="continuous">
    <parent link="base_link"/>
    <child link="front_right_wheel"/>
    <origin rpy="-1.5707963267948966 0 0" xyz="0.12 -0.19 -0.06"/>
    <axis xyz="0 0 1"/>
  </joint>
  <joint name="rear_left_wheel_joint" type="continuous">
    <parent link="base_link"/>
    <child link="rear_left_wheel"/>
    <origin rpy="-1.5707963267948966 0 0" xyz="-0.12 0.19 -0.06"/>
    <axis xyz="0 0 1"/>
  </joint>
  <joint name="rear_right_wheel_joint" type="continuous">
    <parent link="base_link"/>
    <child link="rear_right_wheel"/>
    <origin rpy="-1.5707963267948966 0 0" xyz="-0.12 -0.19 -0.06"/>
    <axis xyz="0 0 1"/>
  </joint>
  <gazebo>
    <plugin filename="libgz-sim-imu-system.so" name="gz::sim::systems::Imu">
  </plugin>
  </gazebo>
  <gazebo reference="imu_mount_joint">
    <preserveFixedJoint>true</preserveFixedJoint>
  </gazebo>
  <gazebo reference="imu_joint">
    <preserveFixedJoint>true</preserveFixedJoint>
  </gazebo>
  <gazebo reference="imu_link">
    <sensor name="imu_sensor" type="imu">
      <always_on>1</always_on>
      <update_rate>100</update_rate>
      <visualize>false</visualize>
      <topic>/imu/data</topic>
      <imu>
        <angular_velocity>
          <x>
            <noise type="gaussian">
              <mean>0.0</mean>
              <stddev>1e-4</stddev>
            </noise>
          </x>
        </angular_velocity>
        <linear_acceleration>
          <x>
            <noise type="gaussian">
              <mean>0.0</mean>
              <stddev>1e-3</stddev>
            </noise>
          </x>
        </linear_acceleration>
      </imu>
    </sensor>
  </gazebo>
  <gazebo>
    <plugin filename="libgz-sim-sensors-system.so" name="gz::sim::systems::Sensors">
      <render_engine>ogre2</render_engine>
    </plugin>
  </gazebo>
  <gazebo reference="lidar_mount_joint">
    <preserveFixedJoint>true</preserveFixedJoint>
  </gazebo>
  <gazebo reference="lidar_joint">
    <preserveFixedJoint>true</preserveFixedJoint>
  </gazebo>
  <gazebo reference="lidar_beam">
    <sensor name="lidar" type="gpu_ray">
      <always_on>1</always_on>
      <visualize>false</visualize>
      <update_rate>10</update_rate>
      <ray>
        <scan>
          <horizontal>
            <samples>360</samples>
            <resolution>1.0</resolution>
            <min_angle>0.0</min_angle>
            <max_angle>6.28319</max_angle>
          </horizontal>
        </scan>
        <range>
          <min>0.1</min>
          <max>10.0</max>
        </range>
      </ray>
      <topic>/scan</topic>
      <gz_frame_id>lidar_beam</gz_frame_id>
    </sensor>
  </gazebo>
  <!-- Contact system plugin (one instance for all bumpers) -->
  <gazebo>
    <plugin filename="libgz-sim-contact-system.so" name="gz::sim::systems::Contact"/>
  </gazebo>
  <gazebo reference="bumper_front_mount_joint">
    <preserveFixedJoint>true</preserveFixedJoint>
  </gazebo>
  <gazebo reference="bumper_front_contact_joint">
    <preserveFixedJoint>true</preserveFixedJoint>
  </gazebo>
  <gazebo reference="bumper_front_mount">
    <sensor name="bumper_front_sensor" type="contact">
      <always_on>1</always_on>
      <update_rate>30</update_rate>
      <topic>/bumper/front</topic>
      <contact>
        <collision>bumper_front_mount_collision</collision>
      </contact>
    </sensor>
  </gazebo>
  <gazebo reference="bumper_rear_mount_joint">
    <preserveFixedJoint>true</preserveFixedJoint>
  </gazebo>
  <gazebo reference="bumper_rear_contact_joint">
    <preserveFixedJoint>true</preserveFixedJoint>
  </gazebo>
  <gazebo reference="bumper_rear_mount">
    <sensor name="bumper_rear_sensor" type="contact">
      <always_on>1</always_on>
      <update_rate>30</update_rate>
      <topic>/bumper/rear</topic>
      <contact>
        <collision>bumper_rear_mount_collision</collision>
      </contact>
    </sensor>
  </gazebo>
  <gazebo reference="bumper_left_mount_joint">
    <preserveFixedJoint>true</preserveFixedJoint>
  </gazebo>
  <gazebo reference="bumper_left_contact_joint">
    <preserveFixedJoint>true</preserveFixedJoint>
  </gazebo>
  <gazebo reference="bumper_left_mount">
    <sensor name="bumper_left_sensor" type="contact">
      <always_on>1</always_on>
      <update_rate>30</update_rate>
      <topic>/bumper/left</topic>
      <contact>
        <collision>bumper_left_mount_collision</collision>
      </contact>
    </sensor>
  </gazebo>
  <gazebo reference="bumper_right_mount_joint">
    <preserveFixedJoint>true</preserveFixedJoint>
  </gazebo>
  <gazebo reference="bumper_right_contact_joint">
    <preserveFixedJoint>true</preserveFixedJoint>
  </gazebo>
  <gazebo reference="bumper_right_mount">
    <sensor name="bumper_right_sensor" type="contact">
      <always_on>1</always_on>
      <update_rate>30</update_rate>
      <topic>/bumper/right</topic>
      <contact>
        <collision>bumper_right_mount_collision</collision>
      </contact>
    </sensor>
  </gazebo>
  <gazebo reference="cliff_sensor_fl_mount_joint">
    <preserveFixedJoint>true</preserveFixedJoint>
  </gazebo>
  <gazebo reference="cliff_sensor_fl_beam_joint">
    <preserveFixedJoint>true</preserveFixedJoint>
  </gazebo>
  <gazebo reference="cliff_sensor_fl_beam">
    <sensor name="cliff_fl" type="gpu_ray">
      <always_on>1</always_on>
      <update_rate>20</update_rate>
      <visualize>true</visualize>
      <ray>
        <scan>
          <horizontal>
            <samples>1</samples>
            <resolution>1</resolution>
            <min_angle>0</min_angle>
            <max_angle>0</max_angle>
          </horizontal>
        </scan>
        <range>
          <min>0.01</min>
          <max>0.5</max>
          <resolution>0.001</resolution>
        </range>
      </ray>
      <topic>/cliff/fl</topic>
      <gz_frame_id>cliff_sensor_fl_beam</gz_frame_id>
    </sensor>
  </gazebo>
  <gazebo reference="cliff_sensor_fr_mount_joint">
    <preserveFixedJoint>true</preserveFixedJoint>
  </gazebo>
  <gazebo reference="cliff_sensor_fr_beam_joint">
    <preserveFixedJoint>true</preserveFixedJoint>
  </gazebo>
  <gazebo reference="cliff_sensor_fr_beam">
    <sensor name="cliff_fr" type="gpu_ray">
      <always_on>1</always_on>
      <update_rate>20</update_rate>
      <visualize>true</visualize>
      <ray>
        <scan>
          <horizontal>
            <samples>1</samples>
            <resolution>1</resolution>
            <min_angle>0</min_angle>
            <max_angle>0</max_angle>
          </horizontal>
        </scan>
        <range>
          <min>0.01</min>
          <max>0.5</max>
          <resolution>0.001</resolution>
        </range>
      </ray>
      <topic>/cliff/fr</topic>
      <gz_frame_id>cliff_sensor_fr_beam</gz_frame_id>
    </sensor>
  </gazebo>
  <gazebo reference="cliff_sensor_rl_mount_joint">
    <preserveFixedJoint>true</preserveFixedJoint>
  </gazebo>
  <gazebo reference="cliff_sensor_rl_beam_joint">
    <preserveFixedJoint>true</preserveFixedJoint>
  </gazebo>
  <gazebo reference="cliff_sensor_rl_beam">
    <sensor name="cliff_rl" type="gpu_ray">
      <always_on>1</always_on>
      <update_rate>20</update_rate>
      <visualize>true</visualize>
      <ray>
        <scan>
          <horizontal>
            <samples>1</samples>
            <resolution>1</resolution>
            <min_angle>0</min_angle>
            <max_angle>0</max_angle>
          </horizontal>
        </scan>
        <range>
          <min>0.01</min>
          <max>0.5</max>
          <resolution>0.001</resolution>
        </range>
      </ray>
      <topic>/cliff/rl</topic>
      <gz_frame_id>cliff_sensor_rl_beam</gz_frame_id>
    </sensor>
  </gazebo>
  <gazebo reference="cliff_sensor_rr_mount_joint">
    <preserveFixedJoint>true</preserveFixedJoint>
  </gazebo>
  <gazebo reference="cliff_sensor_rr_beam_joint">
    <preserveFixedJoint>true</preserveFixedJoint>
  </gazebo>
  <gazebo reference="cliff_sensor_rr_beam">
    <sensor name="cliff_rr" type="gpu_ray">
      <always_on>1</always_on>
      <update_rate>20</update_rate>
      <visualize>true</visualize>
      <ray>
        <scan>
          <horizontal>
            <samples>1</samples>
            <resolution>1</resolution>
            <min_angle>0</min_angle>
            <max_angle>0</max_angle>
          </horizontal>
        </scan>
        <range>
          <min>0.01</min>
          <max>0.5</max>
          <resolution>0.001</resolution>
        </range>
      </ray>
      <topic>/cliff/rr</topic>
      <gz_frame_id>cliff_sensor_rr_beam</gz_frame_id>
    </sensor>
  </gazebo>
  <!-- mecanum or diff/differential -->
  <!-- JOINT STATE plugin -->
  <gazebo>
    <plugin filename="libgz-sim-joint-state-publisher-system.so" name="gz::sim::systems::JointStatePublisher">
      <topic>/joint_states</topic>
    </plugin>
  </gazebo>
  <gazebo>
    <plugin filename="libgz-sim-mecanum-drive-system.so" name="gz::sim::systems::MecanumDrive">
      <front_left_joint>front_left_wheel_joint</front_left_joint>
      <front_right_joint>front_right_wheel_joint</front_right_joint>
      <back_left_joint>rear_left_wheel_joint</back_left_joint>
      <back_right_joint>rear_right_wheel_joint</back_right_joint>
      <wheel_separation>0.38</wheel_separation>
      <wheelbase>0.24</wheelbase>
      <wheel_radius>0.055</wheel_radius>
      <odom_publish_frequency>30</odom_publish_frequency>
      <topic>/cmd_vel</topic>
      <odom_topic>/odom</odom_topic>
      <tf_topic>__unused_tf</tf_topic>
      <frame_id>odom</frame_id>
      <child_frame_id>base_footprint</child_frame_id>
    </plugin>
  </gazebo>
  <gazebo reference="front_left_wheel">
    <collision>
      <surface>
        <friction>
          <ode>
            <mu>1.1</mu>
            <mu2>0.15</mu2>
            <fdir1 gz:expressed_in="base_footprint">1 -1 0</fdir1>
          </ode>
        </friction>
      </surface>
    </collision>
  </gazebo>
  <gazebo reference="front_right_wheel">
    <collision>
      <surface>
        <friction>
          <ode>
            <mu>1.1</mu>
            <mu2>0.15</mu2>
            <fdir1 gz:expressed_in="base_footprint">1 1 0</fdir1>
          </ode>
        </friction>
      </surface>
    </collision>
  </gazebo>
  <gazebo reference="rear_left_wheel">
    <collision>
      <surface>
        <friction>
          <ode>
            <mu>1.1</mu>
            <mu2>0.15</mu2>
            <fdir1 gz:expressed_in="base_footprint">1 1 0</fdir1>
          </ode>
        </friction>
      </surface>
    </collision>
  </gazebo>
  <gazebo reference="rear_right_wheel">
    <collision>
      <surface>
        <friction>
          <ode>
            <mu>1.1</mu>
            <mu2>0.15</mu2>
            <fdir1 gz:expressed_in="base_footprint">1 -1 0</fdir1>
          </ode>
        </friction>
      </surface>
    </collision>
  </gazebo>
</robot>
